package com.johny.tj.integration.jei.multi;

import com.google.common.collect.Lists;
import com.johny.tj.machines.multi.steam.MetaTileEntityMegaBoiler;
import gregtech.api.GTValues;
import gregtech.api.metatileentity.multiblock.MultiblockControllerBase;
import gregtech.common.metatileentities.MetaTileEntities;
import gregtech.common.metatileentities.multi.MetaTileEntityLargeBoiler;
import gregtech.integration.jei.multiblock.MultiblockInfoPage;
import gregtech.integration.jei.multiblock.MultiblockShapeInfo;
import net.minecraft.client.resources.I18n;
import net.minecraft.util.EnumFacing;

import java.util.List;

public class MegaBoilerInfo extends MultiblockInfoPage {

    private final MetaTileEntityLargeBoiler.BoilerType boilerType;
    private final MetaTileEntityMegaBoiler megaBoiler;

    public MegaBoilerInfo(MetaTileEntityLargeBoiler.BoilerType boilerType, MetaTileEntityMegaBoiler megaBoiler) {
        this.boilerType = boilerType;
        this.megaBoiler = megaBoiler;
    }

    @Override
    public MultiblockControllerBase getController() {
        return megaBoiler;
    }

    @Override
    public List<MultiblockShapeInfo> getMatchingShapes() {
        MultiblockShapeInfo shapeInfo = MultiblockShapeInfo.builder()
                .aisle("XXXXXXXXXXXXXXX", "CCCCCCCCCCCCCCC", "CCCCCCCCCCCCCCC", "CCCCCCCCCCCCCCC", "CCCCCCCCCCCCCCC", "CCCCCCCCCCCCCCC", "CCCCCCCCCCCCCCC", "CCCCCCCCCCCCCCC", "CCCCCCCCCCCCCCC", "CCCCCCCCCCCCCCC", "CCCCCCCCCCCCCCC", "CCCCCCCCCCCCCCC", "CCCCCCCCCCCCCCC", "CCCCCCCCCCCCCCC", "CCCCCCCCCCCCCCC", "CCCCCCCCCCCCCCC", "CCCCCCCCCCCCCCC", "CCCCCCCCCCCCCCC", "CCCCCCCCCCCCCCC", "CCCCCCCCCCCCCCC")
                .aisle("XXXXXXXXXXXXXXX", "CPPPPPPPPPPPPPC", "CPPPPPPPPPPPPPC", "CPPPPPPPPPPPPPC", "CPPPPPPPPPPPPPC", "CPPPPPPPPPPPPPC", "CPPPPPPPPPPPPPC", "CPPPPPPPPPPPPPC", "CPPPPPPPPPPPPPC", "CPPPPPPPPPPPPPC", "CPPPPPPPPPPPPPC", "CPPPPPPPPPPPPPC", "CPPPPPPPPPPPPPC", "CPPPPPPPPPPPPPC", "CPPPPPPPPPPPPPC", "CPPPPPPPPPPPPPC", "CPPPPPPPPPPPPPC", "CPPPPPPPPPPPPPC", "CPPPPPPPPPPPPPC", "CCCCCCCCCCCCCCC")
                .aisle("XXXXXXXXXXXXXXX", "CPPPPPPPPPPPPPC", "CPPPPPPPPPPPPPC", "CPPPPPPPPPPPPPC", "CPPPPPPPPPPPPPC", "CPPPPPPPPPPPPPC", "CPPPPPPPPPPPPPC", "CPPPPPPPPPPPPPC", "CPPPPPPPPPPPPPC", "CPPPPPPPPPPPPPC", "CPPPPPPPPPPPPPC", "CPPPPPPPPPPPPPC", "CPPPPPPPPPPPPPC", "CPPPPPPPPPPPPPC", "CPPPPPPPPPPPPPC", "CPPPPPPPPPPPPPC", "CPPPPPPPPPPPPPC", "CPPPPPPPPPPPPPC", "CPPPPPPPPPPPPPC", "CCCCCCCCCCCCCCC")
                .aisle("XXXXXXXXXXXXXXX", "CPPPPPPPPPPPPPC", "CPPPPPPPPPPPPPC", "CPPPPPPPPPPPPPC", "CPPPPPPPPPPPPPC", "CPPPPPPPPPPPPPC", "CPPPPPPPPPPPPPC", "CPPPPPPPPPPPPPC", "CPPPPPPPPPPPPPC", "CPPPPPPPPPPPPPC", "CPPPPPPPPPPPPPC", "CPPPPPPPPPPPPPC", "CPPPPPPPPPPPPPC", "CPPPPPPPPPPPPPC", "CPPPPPPPPPPPPPC", "CPPPPPPPPPPPPPC", "CPPPPPPPPPPPPPC", "CPPPPPPPPPPPPPC", "CPPPPPPPPPPPPPC", "CCCCCCCCCCCCCCC")
                .aisle("XXXXXXXXXXXXXXX", "CPPPPPPPPPPPPPC", "CPPPPPPPPPPPPPC", "CPPPPPPPPPPPPPC", "CPPPPPPPPPPPPPC", "CPPPPPPPPPPPPPC", "CPPPPPPPPPPPPPC", "CPPPPPPPPPPPPPC", "CPPPPPPPPPPPPPC", "CPPPPPPPPPPPPPC", "CPPPPPPPPPPPPPC", "CPPPPPPPPPPPPPC", "CPPPPPPPPPPPPPC", "CPPPPPPPPPPPPPC", "CPPPPPPPPPPPPPC", "CPPPPPPPPPPPPPC", "CPPPPPPPPPPPPPC", "CPPPPPPPPPPPPPC", "CPPPPPPPPPPPPPC", "CCCCCCCCCCCCCCC")
                .aisle("XXXXXXXXXXXXXXX", "CPPPPPPPPPPPPPC", "CPPPPPPPPPPPPPC", "CPPPPPPPPPPPPPC", "CPPPPPPPPPPPPPC", "CPPPPPPPPPPPPPC", "CPPPPPPPPPPPPPC", "CPPPPPPPPPPPPPC", "CPPPPPPPPPPPPPC", "CPPPPPPPPPPPPPC", "CPPPPPPPPPPPPPC", "CPPPPPPPPPPPPPC", "CPPPPPPPPPPPPPC", "CPPPPPPPPPPPPPC", "CPPPPPPPPPPPPPC", "CPPPPPPPPPPPPPC", "CPPPPPPPPPPPPPC", "CPPPPPPPPPPPPPC", "CPPPPPPPPPPPPPC", "CCCCCCCCCCCCCCC")
                .aisle("HXXXXXXXXXXXXXX", "CPPPPPPPPPPPPPC", "CPPPPPPPPPPPPPC", "CPPPPPPPPPPPPPC", "CPPPPPPPPPPPPPC", "CPPPPPPPPPPPPPC", "CPPPPPPPPPPPPPC", "CPPPPPPPPPPPPPC", "CPPPPPPPPPPPPPC", "CPPPPPPPPPPPPPC", "CPPPPPPPPPPPPPC", "CPPPPPPPPPPPPPC", "CPPPPPPPPPPPPPC", "CPPPPPPPPPPPPPC", "CPPPPPPPPPPPPPC", "CPPPPPPPPPPPPPC", "CPPPPPPPPPPPPPC", "CPPPPPPPPPPPPPC", "CPPPPPPPPPPPPPC", "CCCCCCCCCCCCCCC")
                .aisle("XXXXXXXXXXXXXXX", "OPPPPPPPPPPPPPC", "SPPPPPPPPPPPPPC", "CPPPPPPPPPPPPPC", "CPPPPPPPPPPPPPC", "CPPPPPPPPPPPPPC", "CPPPPPPPPPPPPPC", "CPPPPPPPPPPPPPC", "CPPPPPPPPPPPPPC", "CPPPPPPPPPPPPPC", "CPPPPPPPPPPPPPC", "CPPPPPPPPPPPPPC", "CPPPPPPPPPPPPPC", "CPPPPPPPPPPPPPC", "CPPPPPPPPPPPPPC", "CPPPPPPPPPPPPPC", "CPPPPPPPPPPPPPC", "CPPPPPPPPPPPPPC", "CPPPPPPPPPPPPPC", "CCCCCCCCCCCCCCC")
                .aisle("IXXXXXXXXXXXXXX", "CPPPPPPPPPPPPPC", "CPPPPPPPPPPPPPC", "CPPPPPPPPPPPPPC", "CPPPPPPPPPPPPPC", "CPPPPPPPPPPPPPC", "CPPPPPPPPPPPPPC", "CPPPPPPPPPPPPPC", "CPPPPPPPPPPPPPC", "CPPPPPPPPPPPPPC", "CPPPPPPPPPPPPPC", "CPPPPPPPPPPPPPC", "CPPPPPPPPPPPPPC", "CPPPPPPPPPPPPPC", "CPPPPPPPPPPPPPC", "CPPPPPPPPPPPPPC", "CPPPPPPPPPPPPPC", "CPPPPPPPPPPPPPC", "CPPPPPPPPPPPPPC", "CCCCCCCCCCCCCCC")
                .aisle("XXXXXXXXXXXXXXX", "CPPPPPPPPPPPPPC", "CPPPPPPPPPPPPPC", "CPPPPPPPPPPPPPC", "CPPPPPPPPPPPPPC", "CPPPPPPPPPPPPPC", "CPPPPPPPPPPPPPC", "CPPPPPPPPPPPPPC", "CPPPPPPPPPPPPPC", "CPPPPPPPPPPPPPC", "CPPPPPPPPPPPPPC", "CPPPPPPPPPPPPPC", "CPPPPPPPPPPPPPC", "CPPPPPPPPPPPPPC", "CPPPPPPPPPPPPPC", "CPPPPPPPPPPPPPC", "CPPPPPPPPPPPPPC", "CPPPPPPPPPPPPPC", "CPPPPPPPPPPPPPC", "CCCCCCCCCCCCCCC")
                .aisle("XXXXXXXXXXXXXXX", "CPPPPPPPPPPPPPC", "CPPPPPPPPPPPPPC", "CPPPPPPPPPPPPPC", "CPPPPPPPPPPPPPC", "CPPPPPPPPPPPPPC", "CPPPPPPPPPPPPPC", "CPPPPPPPPPPPPPC", "CPPPPPPPPPPPPPC", "CPPPPPPPPPPPPPC", "CPPPPPPPPPPPPPC", "CPPPPPPPPPPPPPC", "CPPPPPPPPPPPPPC", "CPPPPPPPPPPPPPC", "CPPPPPPPPPPPPPC", "CPPPPPPPPPPPPPC", "CPPPPPPPPPPPPPC", "CPPPPPPPPPPPPPC", "CPPPPPPPPPPPPPC", "CCCCCCCCCCCCCCC")
                .aisle("XXXXXXXXXXXXXXX", "CPPPPPPPPPPPPPC", "CPPPPPPPPPPPPPC", "CPPPPPPPPPPPPPC", "CPPPPPPPPPPPPPC", "CPPPPPPPPPPPPPC", "CPPPPPPPPPPPPPC", "CPPPPPPPPPPPPPC", "CPPPPPPPPPPPPPC", "CPPPPPPPPPPPPPC", "CPPPPPPPPPPPPPC", "CPPPPPPPPPPPPPC", "CPPPPPPPPPPPPPC", "CPPPPPPPPPPPPPC", "CPPPPPPPPPPPPPC", "CPPPPPPPPPPPPPC", "CPPPPPPPPPPPPPC", "CPPPPPPPPPPPPPC", "CPPPPPPPPPPPPPC", "CCCCCCCCCCCCCCC")
                .aisle("XXXXXXXXXXXXXXX", "CPPPPPPPPPPPPPC", "CPPPPPPPPPPPPPC", "CPPPPPPPPPPPPPC", "CPPPPPPPPPPPPPC", "CPPPPPPPPPPPPPC", "CPPPPPPPPPPPPPC", "CPPPPPPPPPPPPPC", "CPPPPPPPPPPPPPC", "CPPPPPPPPPPPPPC", "CPPPPPPPPPPPPPC", "CPPPPPPPPPPPPPC", "CPPPPPPPPPPPPPC", "CPPPPPPPPPPPPPC", "CPPPPPPPPPPPPPC", "CPPPPPPPPPPPPPC", "CPPPPPPPPPPPPPC", "CPPPPPPPPPPPPPC", "CPPPPPPPPPPPPPC", "CCCCCCCCCCCCCCC")
                .aisle("XXXXXXXXXXXXXXX", "CPPPPPPPPPPPPPC", "CPPPPPPPPPPPPPC", "CPPPPPPPPPPPPPC", "CPPPPPPPPPPPPPC", "CPPPPPPPPPPPPPC", "CPPPPPPPPPPPPPC", "CPPPPPPPPPPPPPC", "CPPPPPPPPPPPPPC", "CPPPPPPPPPPPPPC", "CPPPPPPPPPPPPPC", "CPPPPPPPPPPPPPC", "CPPPPPPPPPPPPPC", "CPPPPPPPPPPPPPC", "CPPPPPPPPPPPPPC", "CPPPPPPPPPPPPPC", "CPPPPPPPPPPPPPC", "CPPPPPPPPPPPPPC", "CPPPPPPPPPPPPPC", "CCCCCCCCCCCCCCC")
                .aisle("XXXXXXXXXXXXXXX", "CCCCCCCCCCCCCCC", "CCCCCCCCCCCCCCC", "CCCCCCCCCCCCCCC", "CCCCCCCCCCCCCCC", "CCCCCCCCCCCCCCC", "CCCCCCCCCCCCCCC", "CCCCCCCCCCCCCCC", "CCCCCCCCCCCCCCC", "CCCCCCCCCCCCCCC", "CCCCCCCCCCCCCCC", "CCCCCCCCCCCCCCC", "CCCCCCCCCCCCCCC", "CCCCCCCCCCCCCCC", "CCCCCCCCCCCCCCC", "CCCCCCCCCCCCCCC", "CCCCCCCCCCCCCCC", "CCCCCCCCCCCCCCC", "CCCCCCCCCCCCCCC", "CCCCCCCCCCCCCCC")
                .where('S', megaBoiler, EnumFacing.WEST)
                .where('C', boilerType.casingState)
                .where('X', boilerType.fireboxState)
                .where('P', boilerType.pipeState)
                .where('I', MetaTileEntities.ITEM_IMPORT_BUS[GTValues.MAX], EnumFacing.WEST)
                .where('O', MetaTileEntities.FLUID_EXPORT_HATCH[GTValues.MAX], EnumFacing.WEST)
                .where('H', MetaTileEntities.FLUID_IMPORT_HATCH[GTValues.MAX], EnumFacing.EAST)
                .build();
        return Lists.newArrayList(shapeInfo);
    }

    @Override
    public String[] getDescription() {
        return new String[] {
                I18n.format("tj.multiblock.default.description")};
    }

    @Override
    public float getDefaultZoom() {
        return 0.3f;
    }
}
